Workbook

Sheet My Profile
A1: My Profile
A3: Field | B3: Value
A4: Age (years) | B4: 30
A5: Sex / life stage | B5: male
A6: Weight (kg) | B6: 70
A7: Height (cm) | B7: 175
A8: Activity level | B8: moderate
A10: Matched life stage: | B10: =IFERROR(INDEX('DRI Values'!A2:A23, MATCH(1, ('DRI Values'!$B$2:$B$23=$B$5)*('DRI Values'!$C$2:$C$23<=$B$4)*('DRI Values'!$D$2:$D$23>=$B$4), 0)), "no match")

Sheet DRI Values
A1: life_stage_id | B1: sex | C1: age_min | D1: age_max | E1: label | F1: Protein (g/d) | G1: Carbohydrate (g/d) | H1: Total Fiber (g/d) | I1: Fat (g/d) | J1: Calcium (mg/d) | K1: Phosphorus (mg/d) | L1: Magnesium (mg/d) | M1: Potassium (mg/d) | N1: Sodium (mg/d) | O1: Iron (mg/d) | P1: Zinc (mg/d) | Q1: Selenium (ug/d) | R1: Copper (ug/d) | S1: Manganese (mg/d) | T1: Iodine (ug/d) | U1: Vitamin A (RAE) (ug/d) | V1: Vitamin D (ug/d) | W1: Vitamin E (alpha-tocopherol) (mg/d) | X1: Vitamin K (ug/d) | Y1: Vitamin C (mg/d) | Z1: Thiamin (mg/d) | AA1: Riboflavin (mg/d) | AB1: Niacin (mg/d) | AC1: Vitamin B6 (mg/d) | AD1: Folate (DFE) (ug/d) | AE1: Vitamin B12 (ug/d) | AF1: Pantothenic Acid (mg/d) | AG1: Biotin (ug/d) | AH1: Choline (mg/d)
A2: infant_0_6mo | B2: infant | C2: 0 | D2: 0.5 | E2: Infant, 0-6mo | F2: 9.1 | G2: 60 | H2: n/a | I2: 31 | J2: 200 | K2: 100 | L2: 30 | M2: 400 | N2: 110 | O2: 0.27 | P2: 2 | Q2: 15 | R2: 200 | S2: 0.003 | T2: 110 | U2: 400 | V2: 10 | W2: 4 | X2: 2 | Y2: 40 | Z2: 0.2 | AA2: 0.3 | AB2: 2 | AC2: 0.1 | AD2: 65 | AE2: 0.4 | AF2: 1.7 | AG2: 5 | AH2: 125
A3: infant_7_12mo | B3: infant | C3: 0.583 | D3: 1 | E3: Infant, 7-12mo | F3: 11 | G3: 95 | H3: n/a | I3: 30 | J3: 260 | K3: 275 | L3: 75 | M3: 860 | N3: 370 | O3: 11 | P3: 3 | Q3: 20 | R3: 220 | S3: 0.6 | T3: 130 | U3: 500 | V3: 10 | W3: 5 | X3: 2.5 | Y3: 50 | Z3: 0.3 | AA3: 0.4 | AB3: 4 | AC3: 0.3 | AD3: 80 | AE3: 0.5 | AF3: 1.8 | AG3: 6 | AH3: 150
A4: child_1_3 | B4: child | C4: 1 | D4: 3 | E4: Child, 1-3y | F4: 13 | G4: 130 | H4: 19 | I4: n/a | J4: 700 | K4: 460 | L4: 80 | M4: 2000 | N4: 800 | O4: 7 | P4: 3 | Q4: 20 | R4: 340 | S4: 1.2 | T4: 90 | U4: 300 | V4: 15 | W4: 6 | X4: 30 | Y4: 15 | Z4: 0.5 | AA4: 0.5 | AB4: 6 | AC4: 0.5 | AD4: 150 | AE4: 0.9 | AF4: 2 | AG4: 8 | AH4: 200
A5: child_4_8 | B5: child | C5: 4 | D5: 8 | E5: Child, 4-8y | F5: 19 | G5: 130 | H5: 25 | I5: n/a | J5: 1000 | K5: 500 | L5: 130 | M5: 2300 | N5: 1000 | O5: 10 | P5: 5 | Q5: 30 | R5: 440 | S5: 1.5 | T5: 90 | U5: 400 | V5: 15 | W5: 7 | X5: 55 | Y5: 25 | Z5: 0.6 | AA5: 0.6 | AB5: 8 | AC5: 0.6 | AD5: 200 | AE5: 1.2 | AF5: 3 | AG5: 12 | AH5: 250
A6: male_9_13 | B6: male | C6: 9 | D6: 13 | E6: Male, 9-13y | F6: 34 | G6: 130 | H6: 31 | I6: n/a | J6: 1300 | K6: 1250 | L6: 240 | M6: 2500 | N6: 1200 | O6: 8 | P6: 8 | Q6: 40 | R6: 700 | S6: 1.9 | T6: 120 | U6: 600 | V6: 15 | W6: 11 | X6: 60 | Y6: 45 | Z6: 0.9 | AA6: 0.9 | AB6: 12 | AC6: 1 | AD6: 300 | AE6: 1.8 | AF6: 4 | AG6: 20 | AH6: 375
A7: male_14_18 | B7: male | C7: 14 | D7: 18 | E7: Male, 14-18y | F7: 52 | G7: 130 | H7: 38 | I7: n/a | J7: 1300 | K7: 1250 | L7: 410 | M7: 3000 | N7: 1500 | O7: 11 | P7: 11 | Q7: 55 | R7: 890 | S7: 2.2 | T7: 150 | U7: 900 | V7: 15 | W7: 15 | X7: 75 | Y7: 75 | Z7: 1.2 | AA7: 1.3 | AB7: 16 | AC7: 1.3 | AD7: 400 | AE7: 2.4 | AF7: 5 | AG7: 25 | AH7: 550
A8: male_19_30 | B8: male | C8: 19 | D8: 30 | E8: Male, 19-30y | F8: 56 | G8: 130 | H8: 38 | I8: n/a | J8: 1000 | K8: 700 | L8: 400 | M8: 3400 | N8: 1500 | O8: 8 | P8: 11 | Q8: 55 | R8: 900 | S8: 2.3 | T8: 150 | U8: 900 | V8: 15 | W8: 15 | X8: 120 | Y8: 90 | Z8: 1.2 | AA8: 1.3 | AB8: 16 | AC8: 1.3 | AD8: 400 | AE8: 2.4 | AF8: 5 | AG8: 30 | AH8: 550
A9: male_31_50 | B9: male | C9: 31 | D9: 50 | E9: Male, 31-50y | F9: 56 | G9: 130 | H9: 38 | I9: n/a | J9: 1000 | K9: 700 | L9: 420 | M9: 3400 | N9: 1500 | O9: 8 | P9: 11 | Q9: 55 | R9: 900 | S9: 2.3 | T9: 150 | U9: 900 | V9: 15 | W9: 15 | X9: 120 | Y9: 90 | Z9: 1.2 | AA9: 1.3 | AB9: 16 | AC9: 1.3 | AD9: 400 | AE9: 2.4 | AF9: 5 | AG9: 30 | AH9: 550
A10: male_51_70 | B10: male | C10: 51 | D10: 70 | E10: Male, 51-70y | F10: 56 | G10: 130 | H10: 30 | I10: n/a | J10: 1000 | K10: 700 | L10: 420 | M10: 3400 | N10: 1500 | O10: 8 | P10: 11 | Q10: 55 | R10: 900 | S10: 2.3 | T10: 150 | U10: 900 | V10: 15 | W10: 15 | X10: 120 | Y10: 90 | Z10: 1.2 | AA10: 1.3 | AB10: 16 | AC10: 1.7 | AD10: 400 | AE10: 2.4 | AF10: 5 | AG10: 30 | AH10: 550
A11: male_70plus | B11: male | C11: 71 | D11: 200 | E11: Male, 70y+ | F11: 56 | G11: 130 | H11: 30 | I11: n/a | J11: 1200 | K11: 700 | L11: 420 | M11: 3400 | N11: 1500 | O11: 8 | P11: 11 | Q11: 55 | R11: 900 | S11: 2.3 | T11: 150 | U11: 900 | V11: 20 | W11: 15 | X11: 120 | Y11: 90 | Z11: 1.2 | AA11: 1.3 | AB11: 16 | AC11: 1.7 | AD11: 400 | AE11: 2.4 | AF11: 5 | AG11: 30 | AH11: 550
A12: female_9_13 | B12: female | C12: 9 | D12: 13 | E12: Female, 9-13y | F12: 34 | G12: 130 | H12: 26 | I12: n/a | J12: 1300 | K12: 1250 | L12: 240 | M12: 2300 | N12: 1200 | O12: 8 | P12: 8 | Q12: 40 | R12: 700 | S12: 1.6 | T12: 120 | U12: 600 | V12: 15 | W12: 11 | X12: 60 | Y12: 45 | Z12: 0.9 | AA12: 0.9 | AB12: 12 | AC12: 1 | AD12: 300 | AE12: 1.8 | AF12: 4 | AG12: 20 | AH12: 375
A13: female_14_18 | B13: female | C13: 14 | D13: 18 | E13: Female, 14-18y | F13: 46 | G13: 130 | H13: 26 | I13: n/a | J13: 1300 | K13: 1250 | L13: 360 | M13: 2300 | N13: 1500 | O13: 15 | P13: 9 | Q13: 55 | R13: 890 | S13: 1.6 | T13: 150 | U13: 700 | V13: 15 | W13: 15 | X13: 75 | Y13: 65 | Z13: 1 | AA13: 1 | AB13: 14 | AC13: 1.2 | AD13: 400 | AE13: 2.4 | AF13: 5 | AG13: 25 | AH13: 400
A14: female_19_30 | B14: female | C14: 19 | D14: 30 | E14: Female, 19-30y | F14: 46 | G14: 130 | H14: 25 | I14: n/a | J14: 1000 | K14: 700 | L14: 310 | M14: 2600 | N14: 1500 | O14: 18 | P14: 8 | Q14: 55 | R14: 900 | S14: 1.8 | T14: 150 | U14: 700 | V14: 15 | W14: 15 | X14: 90 | Y14: 75 | Z14: 1.1 | AA14: 1.1 | AB14: 14 | AC14: 1.3 | AD14: 400 | AE14: 2.4 | AF14: 5 | AG14: 30 | AH14: 425
A15: female_31_50 | B15: female | C15: 31 | D15: 50 | E15: Female, 31-50y | F15: 46 | G15: 130 | H15: 25 | I15: n/a | J15: 1000 | K15: 700 | L15: 320 | M15: 2600 | N15: 1500 | O15: 18 | P15: 8 | Q15: 55 | R15: 900 | S15: 1.8 | T15: 150 | U15: 700 | V15: 15 | W15: 15 | X15: 90 | Y15: 75 | Z15: 1.1 | AA15: 1.1 | AB15: 14 | AC15: 1.3 | AD15: 400 | AE15: 2.4 | AF15: 5 | AG15: 30 | AH15: 425
... A23: lactating_31_50 | B23: lactating | C23: 31 | D23: 50 | E23: Lactating, 31-50y | F23: 71 | G23: 210 | H23: 29 | I23: n/a | J23: 1000 | K23: 700 | L23: 320 | M23: 2800 | N23: 1500 | O23: 9 | P23: 12 | Q23: 70 | R23: 1300 | S23: 2.6 | T23: 290 | U23: 1300 | V23: 15 | W23: 19 | X23: 90 | Y23: 120 | Z23: 1.4 | AA23: 1.6 | AB23: 17 | AC23: 2 | AD23: 500 | AE23: 2.8 | AF23: 7 | AG23: 35 | AH23: 550
A24: Your personal targets (from My Profile):
E25: YOUR TARGET | F25: =IFERROR(INDEX(F2:F23, MATCH(1, (B2:B23='My Profile'!$B$5)*(C2:C23<='My Profile'!$B$4)*(D2:D23>='My Profile'!$B$4), 0)), "no match") | G25: =IFERROR(INDEX(G2:G23, MATCH(1, (B2:B23='My Profile'!$B$5)*(C2:C23<='My Profile'!$B$4)*(D2:D23>='My Profile'!$B$4), 0)), "no match") | H25: =IFERROR(INDEX(H2:H23, MATCH(1, (B2:B23='My Profile'!$B$5)*(C2:C23<='My Profile'!$B$4)*(D2:D23>='My Profile'!$B$4), 0)), "no match") | I25: =IFERROR(INDEX(I2:I23, MATCH(1, (B2:B23='My Profile'!$B$5)*(C2:C23<='My Profile'!$B$4)*(D2:D23>='My Profile'!$B$4), 0)), "no match") | J25: =IFERROR(INDEX(J2:J23, MATCH(1, (B2:B23='My Profile'!$B$5)*(C2:C23<='My Profile'!$B$4)*(D2:D23>='My Profile'!$B$4), 0)), "no match") | K25: =IFERROR(INDEX(K2:K23, MATCH(1, (B2:B23='My Profile'!$B$5)*(C2:C23<='My Profile'!$B$4)*(D2:D23>='My Profile'!$B$4), 0)), "no match") | L25: =IFERROR(INDEX(L2:L23, MATCH(1, (B2:B23='My Profile'!$B$5)*(C2:C23<='My Profile'!$B$4)*(D2:D23>='My Profile'!$B$4), 0)), "no match") | M25: =IFERROR(INDEX(M2:M23, MATCH(1, (B2:B23='My Profile'!$B$5)*(C2:C23<='My Profile'!$B$4)*(D2:D23>='My Profile'!$B$4), 0)), "no match") | N25: =IFERROR(INDEX(N2:N23, MATCH(1, (B2:B23='My Profile'!$B$5)*(C2:C23<='My Profile'!$B$4)*(D2:D23>='My Profile'!$B$4), 0)), "no match") | O25: =IFERROR(INDEX(O2:O23, MATCH(1, (B2:B23='My Profile'!$B$5)*(C2:C23<='My Profile'!$B$4)*(D2:D23>='My Profile'!$B$4), 0)), "no match") | P25: =IFERROR(INDEX(P2:P23, MATCH(1, (B2:B23='My Profile'!$B$5)*(C2:C23<='My Profile'!$B$4)*(D2:D23>='My Profile'!$B$4), 0)), "no match") | Q25: =IFERROR(INDEX(Q2:Q23, MATCH(1, (B2:B23='My Profile'!$B$5)*(C2:C23<='My Profile'!$B$4)*(D2:D23>='My Profile'!$B$4), 0)), "no match") | R25: =IFERROR(INDEX(R2:R23, MATCH(1, (B2:B23='My Profile'!$B$5)*(C2:C23<='My Profile'!$B$4)*(D2:D23>='My Profile'!$B$4), 0)), "no match") | S25: =IFERROR(INDEX(S2:S23, MATCH(1, (B2:B23='My Profile'!$B$5)*(C2:C23<='My Profile'!$B$4)*(D2:D23>='My Profile'!$B$4), 0)), "no match") | T25: =IFERROR(INDEX(T2:T23, MATCH(1, (B2:B23='My Profile'!$B$5)*(C2:C23<='My Profile'!$B$4)*(D2:D23>='My Profile'!$B$4), 0)), "no match") | U25: =IFERROR(INDEX(U2:U23, MATCH(1, (B2:B23='My Profile'!$B$5)*(C2:C23<='My Profile'!$B$4)*(D2:D23>='My Profile'!$B$4), 0)), "no match") | V25: =IFERROR(INDEX(V2:V23, MATCH(1, (B2:B23='My Profile'!$B$5)*(C2:C23<='My Profile'!$B$4)*(D2:D23>='My Profile'!$B$4), 0)), "no match") | W25: =IFERROR(INDEX(W2:W23, MATCH(1, (B2:B23='My Profile'!$B$5)*(C2:C23<='My Profile'!$B$4)*(D2:D23>='My Profile'!$B$4), 0)), "no match") | X25: =IFERROR(INDEX(X2:X23, MATCH(1, (B2:B23='My Profile'!$B$5)*(C2:C23<='My Profile'!$B$4)*(D2:D23>='My Profile'!$B$4), 0)), "no match") | Y25: =IFERROR(INDEX(Y2:Y23, MATCH(1, (B2:B23='My Profile'!$B$5)*(C2:C23<='My Profile'!$B$4)*(D2:D23>='My Profile'!$B$4), 0)), "no match") | Z25: =IFERROR(INDEX(Z2:Z23, MATCH(1, (B2:B23='My Profile'!$B$5)*(C2:C23<='My Profile'!$B$4)*(D2:D23>='My Profile'!$B$4), 0)), "no match") | AA25: =IFERROR(INDEX(AA2:AA23, MATCH(1, (B2:B23='My Profile'!$B$5)*(C2:C23<='My Profile'!$B$4)*(D2:D23>='My Profile'!$B$4), 0)), "no match") | AB25: =IFERROR(INDEX(AB2:AB23, MATCH(1, (B2:B23='My Profile'!$B$5)*(C2:C23<='My Profile'!$B$4)*(D2:D23>='My Profile'!$B$4), 0)), "no match") | AC25: =IFERROR(INDEX(AC2:AC23, MATCH(1, (B2:B23='My Profile'!$B$5)*(C2:C23<='My Profile'!$B$4)*(D2:D23>='My Profile'!$B$4), 0)), "no match") | AD25: =IFERROR(INDEX(AD2:AD23, MATCH(1, (B2:B23='My Profile'!$B$5)*(C2:C23<='My Profile'!$B$4)*(D2:D23>='My Profile'!$B$4), 0)), "no match") | AE25: =IFERROR(INDEX(AE2:AE23, MATCH(1, (B2:B23='My Profile'!$B$5)*(C2:C23<='My Profile'!$B$4)*(D2:D23>='My Profile'!$B$4), 0)), "no match") | AF25: =IFERROR(INDEX(AF2:AF23, MATCH(1, (B2:B23='My Profile'!$B$5)*(C2:C23<='My Profile'!$B$4)*(D2:D23>='My Profile'!$B$4), 0)), "no match") | AG25: =IFERROR(INDEX(AG2:AG23, MATCH(1, (B2:B23='My Profile'!$B$5)*(C2:C23<='My Profile'!$B$4)*(D2:D23>='My Profile'!$B$4), 0)), "no match") | AH25: =IFERROR(INDEX(AH2:AH23, MATCH(1, (B2:B23='My Profile'!$B$5)*(C2:C23<='My Profile'!$B$4)*(D2:D23>='My Profile'!$B$4), 0)), "no match")

Sheet Food Catalogue
A1: category | B1: name | C1: common_names | D1: fdc_id | E1: source_name | F1: source_url | G1: published_date | H1: calcium_mg | I1: carb_g | J1: choline_mg | K1: copper_ug | L1: fat_g | M1: fiber_g | N1: folate_ug | O1: iron_mg | P1: kcal | Q1: magnesium_mg | R1: manganese_mg | S1: niacin_mg | T1: pantothenic_mg | U1: phosphorus_mg | V1: potassium_mg | W1: protein_g | X1: riboflavin_mg | Y1: sat_fat_g | Z1: selenium_ug | AA1: sodium_mg | AB1: sugar_g | AC1: thiamin_mg | AD1: vitA_ug | AE1: vitB12_ug | AF1: vitB6_mg | AG1: vitC_mg | AH1: vitD_ug | AI1: vitE_mg | AJ1: vitK_ug | AK1: zinc_mg
A2: Meats | B2: Chicken, broilers or fryers, breast, meat only, cooked, roasted | D2: 171477 | E2: USDA FoodData Central, SR Legacy | F2: https://api.nal.usda.gov/fdc/v1/food/171477 | G2: 2019-04-01 | H2: 15 | I2: 0 | J2: 85.3 | K2: no data | L2: 3.57 | M2: 0 | N2: 4 | O2: 1.04 | P2: 165 | Q2: 29 | R2: 0.017 | S2: 13.7 | T2: 0.965 | U2: 228 | V2: 256 | W2: 31 | X2: 0.114 | Y2: 1.01 | Z2: 27.6 | AA2: 74 | AB2: no data | AC2: 0.07 | AD2: 6 | AE2: 0.34 | AF2: 0.6 | AG2: 0 | AH2: 0.1 | AI2: 0.27 | AJ2: 0.3 | AK2: 1
A3: Meats | B3: Chicken, broilers or fryers, thigh, meat only, cooked, roasted | D3: 172388 | E3: USDA FoodData Central, SR Legacy | F3: https://api.nal.usda.gov/fdc/v1/food/172388 | G3: 2019-04-01 | H3: 9 | I3: 0 | J3: 71.8 | K3: no data | L3: 8.15 | M3: 0 | N3: 5 | O3: 1.13 | P3: 179 | Q3: 24 | R3: 0.016 | S3: 6.21 | T3: 1.3 | U3: 230 | V3: 269 | W3: 24.8 | X3: 0.218 | Y3: 2.31 | Z3: 27.1 | AA3: 106 | AB3: no data | AC3: 0.096 | AD3: 8 | AE3: 0.42 | AF3: 0.462 | AG3: 0 | AH3: 0.2 | AI3: 0.18 | AJ3: 3.9 | AK3: 1.92
A4: Meats | B4: Beef, ground, 85% lean meat / 15% fat, patty, cooked, broiled | C4: ground round, hamburger | D4: 174032 | E4: USDA FoodData Central, SR Legacy | F4: https://api.nal.usda.gov/fdc/v1/food/174032 | G4: 2019-04-01 | H4: 18 | I4: 0 | J4: 82.4 | K4: no data | L4: 15.4 | M4: 0 | N4: 9 | O4: 2.6 | P4: 250 | Q4: 21 | R4: 0.012 | S4: 5.38 | T4: 0.658 | U4: 198 | V4: 318 | W4: 25.9 | X4: 0.176 | Y4: 5.9 | Z4: 21.5 | AA4: 72 | AB4: no data | AC4: 0.046 | AD4: 3 | AE4: 2.64 | AF4: 0.382 | AG4: 0 | AH4: 0 | AI4: 0.12 | AJ4: 1.2 | AK4: 6.31
A5: Meats | B5: Beef, ground, 93% lean meat / 7% fat, patty, cooked, broiled | C5: hamburger | D5: 174752 | E5: USDA FoodData Central, SR Legacy | F5: https://api.nal.usda.gov/fdc/v1/food/174752 | G5: 2019-04-01 | H5: 9 | I5: 0 | J5: 84.8 | K5: no data | L5: 8.94 | M5: 0 | N5: 7 | O5: 2.78 | P5: 193 | Q5: 22 | R5: 0.014 | S5: 5.83 | T5: 0.658 | U5: 205 | V5: 342 | W5: 26.2 | X5: 0.176 | Y5: 3.68 | Z5: 21.5 | AA5: 66 | AB5: no data | AC5: 0.043 | AD5: 3 | AE5: 2.51 | AF5: 0.406 | AG5: 0 | AH5: 0 | AI5: 0.12 | AJ5: 1.2 | AK5: 6.41
A6: Meats | B6: Pork, fresh, loin, center loin (chops), bone-in, separable lean only, cooked, broiled | C6: URMIS #3313, Center loin chops, Centercut pork chops, Centercut pork loin chops | D6: 168240 | E6: USDA FoodData Central, SR Legacy | F6: https://api.nal.usda.gov/fdc/v1/food/168240 | G6: 2019-04-01 | H6: 23 | I6: 0 | J6: 76 | K6: no data | L6: 7.29 | M6: 0 | N6: 0 | O6: 0.8 | P6: 180 | Q6: 26 | R6: 0.009 | S6: 8.48 | T6: 0.672 | U6: 228 | V6: 356 | W6: 26.8 | X6: 0.243 | Y6: 2.16 | Z6: 45.7 | AA6: 56 | AB6: no data | AC6: 0.624 | AD6: 0 | AE6: 0.54 | AF6: 0.701 | AG6: 0 | AH6: 0.7 | AI6: 0.1 | AJ6: 0 | AK6: 2.22
A7: Meats | B7: Pork, cured, bacon, pre-sliced, cooked, pan-fried | D7: 168322 | E7: USDA FoodData Central, SR Legacy | F7: https://api.nal.usda.gov/fdc/v1/food/168322 | G7: 2019-04-01 | H7: 11 | I7: 1.7 | J7: 89.5 | K7: no data | L7: 35.1 | M7: 0 | N7: 0 | O7: 0.95 | P7: 468 | Q7: 31 | R7: 0.022 | S7: 10.5 | T7: 1.1 | U7: 388 | V7: 499 | W7: 33.9 | X7: 0.232 | Y7: 12 | Z7: 50.7 | AA7: 1680 | AB7: no data | AC7: 0.56 | AD7: 11 | AE7: 1.09 | AF7: 0.535 | AG7: 0 | AH7: 0.4 | AI7: 0.42 | AJ7: 0 | AK7: 3.06
A8: Meats | B8: Turkey, whole, breast, meat only, cooked, roasted | D8: 171496 | E8: USDA FoodData Central, SR Legacy | F8: https://api.nal.usda.gov/fdc/v1/food/171496 | G8: 2019-04-01 | H8: 9 | I8: 0 | J8: 84.4 | K8: no data | L8: 2.08 | M8: 0 | N8: 9 | O8: 0.71 | P8: 147 | Q8: 32 | R8: 0.011 | S8: 11.8 | T8: 0.9 | U8: 230 | V8: 249 | W8: 30.1 | X8: 0.205 | Y8: 0.593 | Z8: 30.2 | AA8: 99 | AB8: no data | AC8: 0.035 | AD8: 3 | AE8: 0.39 | AF8: 0.807 | AG8: 0 | AH8: 0.3 | AI8: 0.06 | AJ8: 0 | AK8: 1.72
A9: Meats | B9: Turkey, Ground, cooked | D9: 171506 | E9: USDA FoodData Central, SR Legacy | F9: https://api.nal.usda.gov/fdc/v1/food/171506 | G9: 2019-04-01 | H9: 28 | I9: 0 | J9: 78.2 | K9: no data | L9: 10.4 | M9: 0 | N9: 7 | O9: 1.52 | P9: 203 | Q9: 30 | R9: 0.011 | S9: 8.72 | T9: 1.19 | U9: 254 | V9: 294 | W9: 27.4 | X9: 0.211 | Y9: 2.67 | Z9: 31.1 | AA9: 78 | AB9: no data | AC9: 0.077 | AD9: 24 | AE9: 1.34 | AF9: 0.633 | AG9: 0 | AH9: 0.2 | AI9: 0.11 | AJ9: 0 | AK9: 3.11
A10: Meats | B10: Lamb, loin, separable lean only, trimmed to 1/4" fat, choice, cooked, broiled | D10: 172492 | E10: USDA FoodData Central, SR Legacy | F10: https://api.nal.usda.gov/fdc/v1/food/172492 | G10: 2019-04-01 | H10: 19 | I10: 0 | J10: 108 | K10: no data | L10: 9.73 | M10: 0 | N10: 24 | O10: 2 | P10: 216 | Q10: 28 | R10: 0.028 | S10: 6.85 | T10: 0.66 | U10: 226 | V10: 376 | W10: 30 | X10: 0.28 | Y10: 3.48 | Z10: 32.8 | AA10: 84 | AB10: no data | AC10: 0.11 | AD10: 0 | AE10: 2.52 | AF10: 0.16 | AG10: 0 | AH10: 0.1 | AI10: 0.16 | AJ10: 3.9 | AK10: 4.13
A11: Meats | B11: Fish, salmon, Atlantic, wild, cooked, dry heat | D11: 171998 | E11: USDA FoodData Central, SR Legacy | F11: https://api.nal.usda.gov/fdc/v1/food/171998 | G11: 2019-04-01 | H11: 15 | I11: 0 | J11: no data | K11: no data | L11: 8.13 | M11: 0 | N11: 29 | O11: 1.03 | P11: 182 | Q11: 37 | R11: 0.021 | S11: 10.1 | T11: 1.92 | U11: 256 | V11: 628 | W11: 25.4 | X11: 0.487 | Y11: 1.26 | Z11: 46.8 | AA11: 56 | AB11: no data | AC11: 0.275 | AD11: 13 | AE11: 3.05 | AF11: 0.944 | AG11: 0 | AH11: no data | AI11: no data | AJ11: no data | AK11: 0.82
A12: Meats | B12: Fish, tuna, yellowfin, fresh, cooked, dry heat | D12: 172006 | E12: USDA FoodData Central, SR Legacy | F12: https://api.nal.usda.gov/fdc/v1/food/172006 | G12: 2019-04-01 | H12: 4 | I12: 0 | J12: 77.6 | K12: no data | L12: 0.59 | M12: 0 | N12: 2 | O12: 0.92 | P12: 130 | Q12: 42 | R12: 0.013 | S12: 22.1 | T12: 0.334 | U12: 333 | V12: 527 | W12: 29.2 | X12: 0.137 | Y12: 0.205 | Z12: 108 | AA12: 54 | AB12: no data | AC12: 0.134 | AD12: 22 | AE12: 2.35 | AF12: 1.04 | AG12: 0 | AH12: 2 | AI12: 0.29 | AJ12: 0.1 | AK12: 0.45
A13: Meats | B13: Crustaceans, shrimp, mixed species, cooked, moist heat (may contain additives to retain moisture) | D13: 171971 | E13: USDA FoodData Central, SR Legacy | F13: https://api.nal.usda.gov/fdc/v1/food/171971 | G13: 2019-04-01 | H13: 91 | I13: 1.52 | J13: 135 | K13: no data | L13: 1.7 | M13: 0 | N13: 24 | O13: 0.32 | P13: 119 | Q13: 37 | R13: 0.049 | S13: 2.68 | T13: 0.519 | U13: 306 | V13: 170 | W13: 22.8 | X13: 0.024 | Y13: 0.521 | Z13: 49.5 | AA13: 947 | AB13: no data | AC13: 0.032 | AD13: 90 | AE13: 1.66 | AF13: 0.242 | AG13: 0 | AH13: 0.1 | AI13: 2.2 | AJ13: 0.4 | AK13: 1.63
A14: Meats | B14: Fish, cod, Atlantic, cooked, dry heat | D14: 171956 | E14: USDA FoodData Central, SR Legacy | F14: https://api.nal.usda.gov/fdc/v1/food/171956 | G14: 2019-04-01 | H14: 14 | I14: 0 | J14: 83.7 | K14: no data | L14: 0.86 | M14: 0 | N14: 8 | O14: 0.49 | P14: 105 | Q14: 42 | R14: 0.02 | S14: 2.51 | T14: 0.18 | U14: 138 | V14: 244 | W14: 22.8 | X14: 0.079 | Y14: 0.168 | Z14: 37.6 | AA14: 78 | AB14: no data | AC14: 0.088 | AD14: 14 | AE14: 1.05 | AF14: 0.283 | AG14: 1 | AH14: 1.2 | AI14: 0.81 | AJ14: 0.1 | AK14: 0.58
A15: Meats | B15: Egg, whole, cooked, hard-boiled | D15: 173424 | E15: USDA FoodData Central, SR Legacy | F15: https://api.nal.usda.gov/fdc/v1/food/173424 | G15: 2019-04-01 | H15: 50 | I15: 1.12 | J15: 294 | K15: no data | L15: 10.6 | M15: 0 | N15: 44 | O15: 1.19 | P15: 155 | Q15: 10 | R15: 0.026 | S15: 0.064 | T15: 1.4 | U15: 172 | V15: 126 | W15: 12.6 | X15: 0.513 | Y15: 3.27 | Z15: 30.8 | AA15: 124 | AB15: no data | AC15: 0.066 | AD15: 149 | AE15: 1.11 | AF15: 0.121 | AG15: 0 | AH15: 2.2 | AI15: 1.03 | AJ15: 0.3 | AK15: 1.05
A16: Meats | B16: Beef, variety meats and by-products, liver, cooked, pan-fried | D16: 168627 | E16: USDA FoodData Central, SR Legacy | F16: https://api.nal.usda.gov/fdc/v1/food/168627 | G16: 2019-04-01 | H16: 6 | I16: 5.16 | J16: 418 | K16: no data | L16: 4.68 | M16: 0 | N16: 260 | O16: 6.17 | P16: 175 | Q16: 22 | R16: 0.356 | S16: 17.5 | T16: 6.94 | U16: 485 | V16: 351 | W16: 26.5 | X16: 3.42 | Y16: 2.53 | Z16: 32.8 | AA16: 77 | AB16: no data | AC16: 0.177 | AD16: 7740 | AE16: 83.1 | AF16: 1.03 | AG16: 0.7 | AH16: 1.2 | AI16: 0.46 | AJ16: 3.9 | AK16: 5.23
A17: Vegetables | B17: Cabbage, chinese (pak-choi), raw | C17: pak choi, bok choy | D17: 170390 | E17: USDA FoodData Central, SR Legacy | F17: https://api.nal.usda.gov/fdc/v1/food/170390 | G17: 2019-04-01 | H17: 105 | I17: 2.18 | J17: 6.4 | K17: no data | L17: 0.2 | M17: 1 | N17: 66 | O17: 0.8 | P17: 13 | Q17: 19 | R17: 0.159 | S17: 0.5 | T17: 0.088 | U17: 37 | V17: 252 | W17: 1.5 | X17: 0.07 | Y17: 0.027 | Z17: 0.5 | AA17: 65 | AB17: no data | AC17: 0.04 | AD17: 223 | AE17: 0 | AF17: 0.194 | AG17: 45 | AH17: 0 | AI17: 0.09 | AJ17: 45.5 | AK17: 0.19
A18: Vegetables | B18: Cabbage, chinese (pe-tsai), raw | C18: napa cabbage, chinese cabbage, pe-tsai | D18: 169979 | E18: USDA FoodData Central, SR Legacy | F18: https://api.nal.usda.gov/fdc/v1/food/169979 | G18: 2019-04-01 | H18: 77 | I18: 3.23 | J18: 7.6 | K18: no data | L18: 0.2 | M18: 1.2 | N18: 79 | O18: 0.31 | P18: 16 | Q18: 13 | R18: 0.19 | S18: 0.4 | T18: 0.105 | U18: 29 | V18: 238 | W18: 1.2 | X18: 0.05 | Y18: 0.043 | Z18: 0.6 | AA18: 9 | AB18: no data | AC18: 0.04 | AD18: 16 | AE18: 0 | AF18: 0.232 | AG18: 27 | AH18: 0 | AI18: 0.12 | AJ18: 42.9 | AK18: 0.23
A19: Vegetables | B19: Cabbage, raw | D19: 169975 | E19: USDA FoodData Central, SR Legacy | F19: https://api.nal.usda.gov/fdc/v1/food/169975 | G19: 2019-04-01 | H19: 40 | I19: 5.8 | J19: 10.7 | K19: no data | L19: 0.1 | M19: 2.5 | N19: 43 | O19: 0.47 | P19: 25 | Q19: 12 | R19: 0.16 | S19: 0.234 | T19: 0.212 | U19: 26 | V19: 170 | W19: 1.28 | X19: 0.04 | Y19: 0.034 | Z19: 0.3 | AA19: 18 | AB19: no data | AC19: 0.061 | AD19: 5 | AE19: 0 | AF19: 0.124 | AG19: 36.6 | AH19: 0 | AI19: 0.15 | AJ19: 76 | AK19: 0.18
A20: Vegetables | B20: Broccoli, raw | D20: 170379 | E20: USDA FoodData Central, SR Legacy | F20: https://api.nal.usda.gov/fdc/v1/food/170379 | G20: 2019-04-01 | H20: 47 | I20: 6.64 | J20: 18.7 | K20: no data | L20: 0.37 | M20: 2.6 | N20: 63 | O20: 0.73 | P20: 34 | Q20: 21 | R20: 0.21 | S20: 0.639 | T20: 0.573 | U20: 66 | V20: 316 | W20: 2.82 | X20: 0.117 | Y20: 0.114 | Z20: 2.5 | AA20: 33 | AB20: no data | AC20: 0.071 | AD20: 31 | AE20: 0 | AF20: 0.175 | AG20: 89.2 | AH20: 0 | AI20: 0.78 | AJ20: 102 | AK20: 0.41
A21: Vegetables | B21: Spinach, raw | D21: 168462 | E21: USDA FoodData Central, SR Legacy | F21: https://api.nal.usda.gov/fdc/v1/food/168462 | G21: 2019-04-01 | H21: 99 | I21: 3.63 | J21: 19.3 | K21: no data | L21: 0.39 | M21: 2.2 | N21: 194 | O21: 2.71 | P21: 23 | Q21: 79 | R21: 0.897 | S21: 0.724 | T21: 0.065 | U21: 49 | V21: 558 | W21: 2.86 | X21: 0.189 | Y21: 0.063 | Z21: 1 | AA21: 79 | AB21: no data | AC21: 0.078 | AD21: 469 | AE21: 0 | AF21: 0.195 | AG21: 28.1 | AH21: 0 | AI21: 2.03 | AJ21: 483 | AK21: 0.53
A22: Vegetables | B22: Kale, raw | D22: 168421 | E22: USDA FoodData Central, SR Legacy | F22: https://api.nal.usda.gov/fdc/v1/food/168421 | G22: 2019-04-01 | H22: 254 | I22: 4.42 | J22: 0.5 | K22: no data | L22: 1.49 | M22: 4.1 | N22: 62 | O22: 1.6 | P22: 35 | Q22: 33 | R22: 0.92 | S22: 1.18 | T22: 0.37 | U22: 55 | V22: 348 | W22: 2.92 | X22: 0.347 | Y22: 0.178 | Z22: 0.9 | AA22: 53 | AB22: no data | AC22: 0.113 | AD22: 241 | AE22: 0 | AF22: 0.147 | AG22: 93.4 | AH22: 0 | AI22: 0.66 | AJ22: 390 | AK22: 0.39
A23: Vegetables | B23: Carrots, raw | D23: 170393 | E23: USDA FoodData Central, SR Legacy | F23: https://api.nal.usda.gov/fdc/v1/food/170393 | G23: 2019-04-01 | H23: 33 | I23: 9.58 | J23: 8.8 | K23: no data | L23: 0.24 | M23: 2.8 | N23: 19 | O23: 0.3 | P23: 41 | Q23: 12 | R23: 0.143 | S23: 0.983 | T23: 0.273 | U23: 35 | V23: 320 | W23: 0.93 | X23: 0.058 | Y23: 0.032 | Z23: 0.1 | AA23: 69 | AB23: no data | AC23: 0.066 | AD23: 835 | AE23: 0 | AF23: 0.138 | AG23: 5.9 | AH23: 0 | AI23: 0.66 | AJ23: 13.2 | AK23: 0.24
A24: Vegetables | B24: Sweet potato, cooked, baked in skin, flesh, without salt | C24: Sweetpotato | D24: 168483 | E24: USDA FoodData Central, SR Legacy | F24: https://api.nal.usda.gov/fdc/v1/food/168483 | G24: 2019-04-01 | H24: 38 | I24: 20.7 | J24: 13.1 | K24: no data | L24: 0.15 | M24: 3.3 | N24: 6 | O24: 0.69 | P24: 90 | Q24: 27 | R24: 0.497 | S24: 1.49 | T24: 0.884 | U24: 54 | V24: 475 | W24: 2.01 | X24: 0.106 | Y24: 0.052 | Z24: 0.2 | AA24: 36 | AB24: no data | AC24: 0.107 | AD24: 961 | AE24: 0 | AF24: 0.286 | AG24: 19.6 | AH24: 0 | AI24: 0.71 | AJ24: 2.3 | AK24: 0.32
A25: Vegetables | B25: Potatoes, baked, flesh and skin, without salt | D25: 170093 | E25: USDA FoodData Central, SR Legacy | F25: https://api.nal.usda.gov/fdc/v1/food/170093 | G25: 2019-04-01 | H25: 15 | I25: 21.2 | J25: 14.8 | K25: no data | L25: 0.13 | M25: 2.2 | N25: 28 | O25: 1.08 | P25: 93 | Q25: 28 | R25: 0.219 | S25: 1.41 | T25: 0.376 | U25: 70 | V25: 535 | W25: 2.5 | X25: 0.048 | Y25: 0.034 | Z25: 0.4 | AA25: 10 | AB25: no data | AC25: 0.064 | AD25: 1 | AE25: 0 | AF25: 0.311 | AG25: 9.6 | AH25: 0 | AI25: 0.04 | AJ25: 2 | AK25: 0.36
A26: Vegetables | B26: Tomatoes, red, ripe, raw, year round average | D26: 170457 | E26: USDA FoodData Central, SR Legacy | F26: https://api.nal.usda.gov/fdc/v1/food/170457 | G26: 2019-04-01 | H26: 10 | I26: 3.89 | J26: 6.7 | K26: no data | L26: 0.2 | M26: 1.2 | N26: 15 | O26: 0.27 | P26: 18 | Q26: 11 | R26: 0.114 | S26: 0.594 | T26: 0.089 | U26: 24 | V26: 237 | W26: 0.88 | X26: 0.019 | Y26: 0.028 | Z26: 0 | AA26: 5 | AB26: no data | AC26: 0.037 | AD26: 42 | AE26: 0 | AF26: 0.08 | AG26: 13.7 | AH26: 0 | AI26: 0.54 | AJ26: 7.9 | AK26: 0.17
A27: Vegetables | B27: Cucumber, with peel, raw | D27: 168409 | E27: USDA FoodData Central, SR Legacy | F27: https://api.nal.usda.gov/fdc/v1/food/168409 | G27: 2019-04-01 | H27: 16 | I27: 3.63 | J27: 6 | K27: no data | L27: 0.11 | M27: 0.5 | N27: 7 | O27: 0.28 | P27: 15 | Q27: 13 | R27: 0.079 | S27: 0.098 | T27: 0.259 | U27: 24 | V27: 147 | W27: 0.65 | X27: 0.033 | Y27: 0.037 | Z27: 0.3 | AA27: 2 | AB27: no data | AC27: 0.027 | AD27: 5 | AE27: 0 | AF27: 0.04 | AG27: 2.8 | AH27: 0 | AI27: 0.03 | AJ27: 16.4 | AK27: 0.2
A28: Vegetables | B28: Peppers, sweet, red, raw | D28: 170108 | E28: USDA FoodData Central, SR Legacy | F28: https://api.nal.usda.gov/fdc/v1/food/170108 | G28: 2019-04-01 | H28: 7 | I28: 6.03 | J28: 5.6 | K28: no data | L28: 0.3 | M28: 2.1 | N28: 46 | O28: 0.43 | P28: 26 | Q28: 12 | R28: 0.112 | S28: 0.979 | T28: 0.317 | U28: 26 | V28: 211 | W28: 0.99 | X28: 0.085 | Y28: 0.059 | Z28: 0.1 | AA28: 4 | AB28: no data | AC28: 0.054 | AD28: 157 | AE28: 0 | AF28: 0.291 | AG28: 128 | AH28: 0 | AI28: 1.58 | AJ28: 4.9 | AK28: 0.25
A29: Vegetables | B29: Onions, raw | D29: 170000 | E29: USDA FoodData Central, SR Legacy | F29: https://api.nal.usda.gov/fdc/v1/food/170000 | G29: 2019-04-01 | H29: 23 | I29: 9.34 | J29: 6.1 | K29: no data | L29: 0.1 | M29: 1.7 | N29: 19 | O29: 0.21 | P29: 40 | Q29: 10 | R29: 0.129 | S29: 0.116 | T29: 0.123 | U29: 29 | V29: 146 | W29: 1.1 | X29: 0.027 | Y29: 0.042 | Z29: 0.5 | AA29: 4 | AB29: no data | AC29: 0.046 | AD29: 0 | AE29: 0 | AF29: 0.12 | AG29: 7.4 | AH29: 0 | AI29: 0.02 | AJ29: 0.4 | AK29: 0.17
A30: Vegetables | B30: Garlic, raw | D30: 169230 | E30: USDA FoodData Central, SR Legacy | F30: https://api.nal.usda.gov/fdc/v1/food/169230 | G30: 2019-04-01 | H30: 181 | I30: 33.1 | J30: 23.2 | K30: no data | L30: 0.5 | M30: 2.1 | N30: 3 | O30: 1.7 | P30: 149 | Q30: 25 | R30: 1.67 | S30: 0.7 | T30: 0.596 | U30: 153 | V30: 401 | W30: 6.36 | X30: 0.11 | Y30: 0.089 | Z30: 14.2 | AA30: 17 | AB30: no data | AC30: 0.2 | AD30: 0 | AE30: 0 | AF30: 1.24 | AG30: 31.2 | AH30: 0 | AI30: 0.08 | AJ30: 1.7 | AK30: 1.16
A31: Vegetables | B31: Beans, snap, green, cooked, boiled, drained, without salt | D31: 169141 | E31: USDA FoodData Central, SR Legacy | F31: https://api.nal.usda.gov/fdc/v1/food/169141 | G31: 2019-04-01 | H31: 44 | I31: 7.88 | J31: 16.9 | K31: no data | L31: 0.28 | M31: 3.2 | N31: 33 | O31: 0.65 | P31: 35 | Q31: 18 | R31: 0.285 | S31: 0.614 | T31: 0.074 | U31: 29 | V31: 146 | W31: 1.89 | X31: 0.097 | Y31: 0.064 | Z31: 0.2 | AA31: 1 | AB31: no data | AC31: 0.074 | AD31: 32 | AE31: 0 | AF31: 0.056 | AG31: 9.7 | AH31: 0 | AI31: 0.46 | AJ31: 47.9 | AK31: 0.25
A32: Vegetables | B32: Squash, summer, zucchini, includes skin, raw | D32: 169291 | E32: USDA FoodData Central, SR Legacy | F32: https://api.nal.usda.gov/fdc/v1/food/169291 | G32: 2019-04-01 | H32: 16 | I32: 3.11 | J32: 9.5 | K32: no data | L32: 0.32 | M32: 1 | N32: 24 | O32: 0.37 | P32: 17 | Q32: 18 | R32: 0.177 | S32: 0.451 | T32: 0.204 | U32: 38 | V32: 261 | W32: 1.21 | X32: 0.094 | Y32: 0.084 | Z32: 0.2 | AA32: 8 | AB32: no data | AC32: 0.045 | AD32: 10 | AE32: 0 | AF32: 0.163 | AG32: 17.9 | AH32: 0 | AI32: 0.12 | AJ32: 4.3 | AK32: 0.32
A33: Vegetables | B33: Cauliflower, raw | D33: 169986 | E33: USDA FoodData Central, SR Legacy | F33: https://api.nal.usda.gov/fdc/v1/food/169986 | G33: 2019-04-01 | H33: 22 | I33: 4.97 | J33: 44.3 | K33: no data | L33: 0.28 | M33: 2 | N33: 57 | O33: 0.42 | P33: 25 | Q33: 15 | R33: 0.155 | S33: 0.507 | T33: 0.667 | U33: 44 | V33: 299 | W33: 1.92 | X33: 0.06 | Y33: 0.13 | Z33: 0.6 | AA33: 30 | AB33: no data | AC33: 0.05 | AD33: 0 | AE33: 0 | AF33: 0.184 | AG33: 48.2 | AH33: 0 | AI33: 0.08 | AJ33: 15.5 | AK33: 0.27
A34: Vegetables | B34: Brussels sprouts, cooked, boiled, drained, without salt | D34: 169971 | E34: USDA FoodData Central, SR Legacy | F34: https://api.nal.usda.gov/fdc/v1/food/169971 | G34: 2019-04-01 | H34: 36 | I34: 7.1 | J34: 40.6 | K34: no data | L34: 0.5 | M34: 2.6 | N34: 60 | O34: 1.2 | P34: 36 | Q34: 20 | R34: 0.227 | S34: 0.607 | T34: 0.252 | U34: 56 | V34: 317 | W34: 2.55 | X34: 0.08 | Y34: 0.102 | Z34: 1.5 | AA34: 21 | AB34: no data | AC34: 0.107 | AD34: 39 | AE34: 0 | AF34: 0.178 | AG34: 62 | AH34: 0 | AI34: 0.43 | AJ34: 140 | AK34: 0.33
A35: Vegetables | B35: Asparagus, cooked, boiled, drained | D35: 168390 | E35: USDA FoodData Central, SR Legacy | F35: https://api.nal.usda.gov/fdc/v1/food/168390 | G35: 2019-04-01 | H35: 23 | I35: 4.11 | J35: 26.1 | K35: no data | L35: 0.22 | M35: 2 | N35: 149 | O35: 0.91 | P35: 22 | Q35: 14 | R35: 0.154 | S35: 1.08 | T35: 0.225 | U35: 54 | V35: 224 | W35: 2.4 | X35: 0.139 | Y35: 0.048 | Z35: 6.1 | AA35: 14 | AB35: no data | AC35: 0.162 | AD35: 50 | AE35: 0 | AF35: 0.079 | AG35: 7.7 | AH35: 0 | AI35: 1.5 | AJ35: 50.6 | AK35: 0.6
A36: Vegetables | B36: Mushrooms, white, raw | D36: 169251 | E36: USDA FoodData Central, SR Legacy | F36: https://api.nal.usda.gov/fdc/v1/food/169251 | G36: 2019-04-01 | H36: 3 | I36: 3.26 | J36: 17.3 | K36: no data | L36: 0.34 | M36: 1 | N36: 17 | O36: 0.5 | P36: 22 | Q36: 9 | R36: 0.047 | S36: 3.61 | T36: 1.5 | U36: 86 | V36: 318 | W36: 3.09 | X36: 0.402 | Y36: 0.05 | Z36: 9.3 | AA36: 5 | AB36: no data | AC36: 0.081 | AD36: 0 | AE36: 0.04 | AF36: 0.104 | AG36: 2.1 | AH36: 0.2 | AI36: 0.01 | AJ36: 0 | AK36: 0.52
... A53: Fruits | B53: Pears, raw | D53: 169118 | E53: USDA FoodData Central, SR Legacy | F53: https://api.nal.usda.gov/fdc/v1/food/169118 | G53: 2019-04-01 | H53: 9 | I53: 15.2 | J53: 5.1 | K53: no data | L53: 0.14 | M53: 3.1 | N53: 7 | O53: 0.18 | P53: 57 | Q53: 7 | R53: 0.048 | S53: 0.161 | T53: 0.049 | U53: 12 | V53: 116 | W53: 0.36 | X53: 0.026 | Y53: 0.022 | Z53: 0.1 | AA53: 1 | AB53: no data | AC53: 0.012 | AD53: 1 | AE53: 0 | AF53: 0.029 | AG53: 4.3 | AH53: 0 | AI53: 0.12 | AJ53: 4.4 | AK53: 0.1
A54: Fruits | B54: Kiwifruit, green, raw | C54: Chinese gooseberry | D54: 168153 | E54: USDA FoodData Central, SR Legacy | F54: https://api.nal.usda.gov/fdc/v1/food/168153 | G54: 2019-04-01 | H54: 34 | I54: 14.7 | J54: 7.8 | K54: no data | L54: 0.52 | M54: 3 | N54: 25 | O54: 0.31 | P54: 61 | Q54: 17 | R54: 0.098 | S54: 0.341 | T54: 0.183 | U54: 34 | V54: 312 | W54: 1.14 | X54: 0.025 | Y54: 0.029 | Z54: 0.2 | AA54: 3 | AB54: no data | AC54: 0.027 | AD54: 4 | AE54: 0 | AF54: 0.063 | AG54: 92.7 | AH54: 0 | AI54: 1.46 | AJ54: 40.3 | AK54: 0.14
A55: Fruits | B55: Avocados, raw, all commercial varieties | D55: 171705 | E55: USDA FoodData Central, SR Legacy | F55: https://api.nal.usda.gov/fdc/v1/food/171705 | G55: 2019-04-01 | H55: 12 | I55: 8.53 | J55: 14.2 | K55: no data | L55: 14.7 | M55: 6.7 | N55: 81 | O55: 0.55 | P55: 160 | Q55: 29 | R55: 0.142 | S55: 1.74 | T55: 1.39 | U55: 52 | V55: 485 | W55: 2 | X55: 0.13 | Y55: 2.13 | Z55: 0.4 | AA55: 7 | AB55: no data | AC55: 0.067 | AD55: 7 | AE55: 0 | AF55: 0.257 | AG55: 10 | AH55: 0 | AI55: 2.07 | AJ55: 21 | AK55: 0.64
A56: Fruits | B56: Lemons, raw, without peel | D56: 167746 | E56: USDA FoodData Central, SR Legacy | F56: https://api.nal.usda.gov/fdc/v1/food/167746 | G56: 2019-04-01 | H56: 26 | I56: 9.32 | J56: 5.1 | K56: no data | L56: 0.3 | M56: 2.8 | N56: 11 | O56: 0.6 | P56: 29 | Q56: 8 | R56: 0.03 | S56: 0.1 | T56: 0.19 | U56: 16 | V56: 138 | W56: 1.1 | X56: 0.02 | Y56: 0.039 | Z56: 0.4 | AA56: 2 | AB56: no data | AC56: 0.04 | AD56: 1 | AE56: 0 | AF56: 0.08 | AG56: 53 | AH56: 0 | AI56: 0.15 | AJ56: 0 | AK56: 0.06
...

Sheet Sources & Notes
A1: Sources & Notes
A3: Nutrient requirements (DRI Values sheet):
A4: National Academies of Sciences, Engineering, and Medicine (NASEM/IOM),
A5: Dietary Reference Intakes Summary Tables -- NCBI Bookshelf NBK545442
A6: (https://www.ncbi.nlm.nih.gov/books/NBK545442/). See app/data/dri_sources.md
A7: in the project repository for the exact table citations used per nutrient.
A9: Food nutrient values (Food Catalogue sheet):
A10: USDA FoodData Central, SR Legacy. Every row includes its own fdc_id and
A11: source_url pointing to the exact FDC record used -- values are fetched,
A12: never estimated. Fetched via scripts/fetch_foods.py.
A14: KNOWN DATA GAP -- Iodine and Biotin:
A15: USDA FoodData Central (SR Legacy) does not measure iodine or biotin in
... A28: advice from a registered dietitian or physician.
